hi , nice tutorial ! thanks effort , really appreciate . wondering deploy chatbot cloud online platform get public url ? would like deploy chatbot backend , deploy get url , add url full-stack-application .
hi sir . pursuing engineering ai & amp ; ml currently 4th semester.so , time , chosen dbms project chatbot.my teacher told team use python flask mongodb.i definitely refer video . used mongodb . ok build project using flask ? also , need submit 1st project review tell attribute entity using ? , please tell write attribute entity ?
link sourcecode & # 39 ; work .
seen video yet want confirm python code want run chatbot video one watch ?
module & # 39 ; time & # 39 ; attribute & # 39 ; clock & # 39 ;
1. reading comments.2 . resolving errors.3 . getting new errors.4 . reading comments.5 . resolving errors.6 . got new error.7 . comment end ☹️
algorithm use dataset
could please post source code ?
possible use different chatbot ? could integration dialogflow possible ?
chatterbot import chatbot importerror : import name & # 39 ; chatbot & # 39 ; & # 39 ; chatterbot & # 39 ; ( c : \users\bhavani\appdata\local\programs\python\python39\lib\site-packages\chatterbot\__init__.py ) facing error anyone help
hello sir error end execute program give error sample.py line 5 also give time attribute error
value search_text available provided input
geting error anybody help self.need_more_tokens ( ) : typeerror : & # 39 ; nonetype & # 39 ; object callable
hi , could easily follow upto final training bot working browser . even send button responding , please look guide resolve error
file & quot ; c : \users\aleky\cbot\sam.py & quot ; , line 6 , & lt ; module & gt ; english_bot = chatbot ( & quot ; chatterbot & quot ; , storage_adapter= & quot ; chatterbot.storage.sqlstorageadapter & quot ; ) file & quot ; c : \users\aleky\appdata\roaming\python\python39\site-packages\chatterbot\chatterbot.py & quot ; , line 35 , _init_ self.storage = utils.initialize_class ( storage_adapter , * * kwargs ) file & quot ; c : \users\aleky\appdata\roaming\python\python39\site-packages\chatterbot\utils.py & quot ; , line 54 , initialize_class return class ( * args , * * kwargs ) file & quot ; c : \users\aleky\appdata\roaming\python\python39\site-packages\chatterbot\storage\sql_storage.py & quot ; , line 46 , _init_ self.engine.dialect.has_table ( self.engine , & # 39 ; statement & # 39 ; ) : file & quot ; c : \users\aleky\appdata\roaming\python\python39\site-packages\sqlalchemy\dialects\sqlite\base.py & quot ; , line 2009 , has_table self._ensure_has_table_connection ( connection ) file & quot ; c : \users\aleky\appdata\roaming\python\python39\site-packages\sqlalchemy\engine\default.py & quot ; , line 341 , _ensure_has_table_connection raise exc.argumenterror ( sqlalchemy.exc.argumenterror : argument passed dialect.has_table ( ) & lt ; class & # 39 ; sqlalchemy.engine.base.connection & # 39 ; & gt ; , got & lt ; class & # 39 ; sqlalchemy.engine.base.engine & # 39 ; & gt ; . additionally , dialect.has_table ( ) method internal dialect use ; please use `` inspect ( some_engine ) .has_table ( & lt ; tablename & gt ; & gt ; ) `` public api use .
oserror : [ e050 ] & # 39 ; find model & # 39 ; en & # 39 ; . & # 39 ; seem shortcut link , python package valid path data directory .
anyone tell error occurinng attributeerror : module & # 39 ; time & # 39 ; attribute & # 39 ; clock & # 39 ;
sir existing website want add chatbot ? change url route function ?
thanks video sir , delete ai.yml , conversation.yml etc file ? ?
hey bro getting errortime_func = time.clockattributeerror : module & # 39 ; time & # 39 ; attribute & # 39 ; clock & # 39 ;
put code github google drive . trust download file computer ? ? professional use github
& # 39 ; getting error . help ? 127.0.0.1 - - [ 04/apr/2021 23:56:47 ] & quot ; get /get ? msg=hai http/1.1 & quot ; 200 - value search_text available provided input
excellent
hey wan na cloud computing based project u give idea
import flask ? key press ?
make api chatterbot added server . ?
question flask provide lstm layer ? create data set generically data set word tag form sentence without lstm layer & amp ; build bot flask ...
raise ioerror ( errors.e050.format ( name=name ) ) oserror : [ e050 ] & # 39 ; find model & # 39 ; en & # 39 ; . & # 39 ; seem shortcut link , python package valid path data directory.this error.have installed ! python -m spacy download en_core_web_lg ! python -m spacy download en_core_web_smbut still working
surrender
excellent tutorial . really helped . thanks much
couldnot download code file seems unknown format damaged .
thanks explanation getting error trying ? help suggestion please ? today & # 39 ; date : 2020-12-27 traceback ( recent call last ) : file & quot ; c : \python39\bot\sample.py & quot ; , line 10 , & lt ; module & gt ; english_bot = chatbot ( & quot ; chatterbot & quot ; , storage_adapter= & quot ; chatterbot.storage.sqlstorageadapter & quot ; ) file & quot ; c : \python39\lib\site-packages\chatterbot\chatterbot.py & quot ; , line 35 , _init_ self.storage = utils.initialize_class ( storage_adapter , * * kwargs ) file & quot ; c : \python39\lib\site-packages\chatterbot\utils.py & quot ; , line 54 , initialize_class return class ( * args , * * kwargs ) file & quot ; c : \python39\lib\site-packages\chatterbot\storage\sql_storage.py & quot ; , line 22 , _init_ sqlalchemy import create_engine file & quot ; c : \python39\lib\site-packages\sqlalchemy\__init__.py & quot ; , line 8 , & lt ; module & gt ; . import util _util # noqa file & quot ; c : \python39\lib\site-packages\sqlalchemy\util\__init__.py & quot ; , line 14 , & lt ; module & gt ; ._collections import coerce_generator_arg # noqa file & quot ; c : \python39\lib\site-packages\sqlalchemy\util\_collections.py & quot ; , line 16 , & lt ; module & gt ; .compat import binary_types file & quot ; c : \python39\lib\site-packages\sqlalchemy\util\compat.py & quot ; , line 264 , & lt ; module & gt ; time_func = time.clock attributeerror : module & # 39 ; time & # 39 ; attribute & # 39 ; clock & # 39 ;
deploy web ? localhost , make accessible others ?
running python 3.6 error file & quot ; sample.py & quot ; , line 8 , & lt ; module & gt ; trainer.train ( & quot ; chatterbot.corpus.english & quot ; )
sir error , could please tell come error traceback ( recent call last ) : file & quot ; sample.py & quot ; , line 9 , & lt ; module & gt ; trainer.train ( & quot ; data/data.yml & quot ; ) file & quot ; c : \programdata\anaconda3\lib\site-packages\chatterbot\trainers.py & quot ; , line 138 , train corpus , category , file_path load_corpus ( * data_file_paths ) : file & quot ; c : \programdata\anaconda3\lib\site-packages\chatterbot\corpus.py & quot ; , line 64 , load_corpus corpus_data = read_corpus ( file_path ) file & quot ; c : \programdata\anaconda3\lib\site-packages\chatterbot\corpus.py & quot ; , line 38 , read_corpus return yaml.load ( data_file ) file & quot ; c : \programdata\anaconda3\lib\site-packages\yaml\__init__.py & quot ; , line 72 , load return loader.get_single_data ( ) file & quot ; c : \programdata\anaconda3\lib\site-packages\yaml\constructor.py & quot ; , line 35 , get_single_data node = self.get_single_node ( ) file & quot ; c : \programdata\anaconda3\lib\site-packages\yaml\composer.py & quot ; , line 36 , get_single_node document = self.compose_document ( ) file & quot ; c : \programdata\anaconda3\lib\site-packages\yaml\composer.py & quot ; , line 55 , compose_document node = self.compose_node ( none , none ) file & quot ; c : \programdata\anaconda3\lib\site-packages\yaml\composer.py & quot ; , line 84 , compose_node node = self.compose_mapping_node ( anchor ) file & quot ; c : \programdata\anaconda3\lib\site-packages\yaml\composer.py & quot ; , line 133 , compose_mapping_node item_value = self.compose_node ( node , item_key ) file & quot ; c : \programdata\anaconda3\lib\site-packages\yaml\composer.py & quot ; , line 82 , compose_node node = self.compose_sequence_node ( anchor ) file & quot ; c : \programdata\anaconda3\lib\site-packages\yaml\composer.py & quot ; , line 110 , compose_sequence_node self.check_event ( sequenceendevent ) : file & quot ; c : \programdata\anaconda3\lib\site-packages\yaml\parser.py & quot ; , line 98 , check_event self.current_event = self.state ( ) file & quot ; c : \programdata\anaconda3\lib\site-packages\yaml\parser.py & quot ; , line 403 , parse_indentless_sequence_entry self.check_token ( blockentrytoken ) : file & quot ; c : \programdata\anaconda3\lib\site-packages\yaml\scanner.py & quot ; , line 115 , check_token self.need_more_tokens ( ) : file & quot ; c : \programdata\anaconda3\lib\site-packages\yaml\scanner.py & quot ; , line 149 , need_more_tokens self.stale_possible_simple_keys ( ) file & quot ; c : \programdata\anaconda3\lib\site-packages\yaml\scanner.py & quot ; , line 289 , stale_possible_simple_keys & quot ; could find expected & # 39 ; : & # 39 ; & quot ; , self.get_mark ( ) ) yaml.scanner.scannererror : scanning simple key & quot ; data/data.yml & quot ; , line 3 , column 1 could find expected & # 39 ; : & # 39 ; & quot ; data/data.yml & quot ; , line 4 , column 1
getting error running code . module & # 39 ; time & # 39 ; attribute & # 39 ; clock & # 39 ; . please help .
hello sir , get big conversation data train bot ?
hello , thank video ! problem running chatbot : installed library everything , code seems correct , bot still & # 39 ; respond browser , could tell issue might ?
hello , getting error.traceback ( recent call last ) : file & quot ; bot.py & quot ; , line 8 , & lt ; module & gt ; trainer.train ( & quot ; data/data.yml & quot ; ) file & quot ; c : \python38\lib\site-packages\chatterbot\trainers.py & quot ; , line 157 , train statement_search_text = self.chatbot.storage.tagger.get_bigram_pair_string ( text ) file & quot ; c : \python38\lib\site-packages\chatterbot\tagging.py & quot ; , line 135 , get_bigram_pair_string sentence self.tokenize_sentence ( text.strip ( ) ) : attributeerror : & # 39 ; bool & # 39 ; object attribute & # 39 ; strip & # 39 ;
hello sir one error en model giving link sir
someone please help ... chatbot doesnt reply , whatever type display go next line waiting type hit send ...
tried python 3.7.9 , getting error running : if_name_ == & quot ; __main__ & quot ; : syntax error : invalid syntax
getting error python 3.9.0
if_name_ == & quot ; __main__ & quot ; : syntax error : invalid syntax
get chat widget ? like talking bottom right instead full page .
sir please say solve errorattributeerror : module & # 39 ; time & # 39 ; attribute & # 39 ; clock & # 39 ;
url found sowht ? ? ?
import flask wht next step ? ? nt coming back normal
appreciate effort . way , explained everything awesome . weldone
code pls - arunncorp01 @ gmail.com
getting error pls helptraceback ( recent call last ) : file & quot ; sample.py & quot ; , line 9 , & lt ; module & gt ; trainer.train ( & quot ; data/data.yml & quot ; )
& # 39 ; getting error oserror : [ e050 ] & # 39 ; find model & # 39 ; en & # 39 ; . & # 39 ; seem shortcut link , python package valid path data directory .
sir , & # 39 ; getting error eve installing pytzc : \users\lenovo\desktop\bot & gt ; python bot.py traceback ( recent call last ) : file & quot ; bot.py & quot ; , line 6 , & lt ; module & gt ; english_bot=chatbot ( & quot ; chatterbot & quot ; , storage_adapter= & quot ; chatter.storage.sqlstorageadapter & quot ; ) file & quot ; c : \users\lenovo\appdata\local\packages\pythonsoftwarefoundation.python.3.8_qbz5n2kfra8p0\localcache\local-packages\python38\site-packages\chatterbot\chatterbot.py & quot ; , line 30 , _init_ utils.validate_adapter_class ( storage_adapter , storageadapter ) file & quot ; c : \users\lenovo\appdata\local\packages\pythonsoftwarefoundation.python.3.8_qbz5n2kfra8p0\localcache\local-packages\python38\site-packages\chatterbot\utils.py & quot ; , line 85 , validate_adapter_class issubclass ( import_module ( validate_class ) , adapter_class ) : file & quot ; c : \users\lenovo\appdata\local\packages\pythonsoftwarefoundation.python.3.8_qbz5n2kfra8p0\localcache\local-packages\python38\site-packages\chatterbot\utils.py & quot ; , line 16 , import_module module = importlib.import_module ( module_path ) file & quot ; c : \program files\windowsapps\pythonsoftwarefoundation.python.3.8_3.8.1520.0_x64__qbz5n2kfra8p0\lib\importlib\__init__.py & quot ; , line 127 , import_module return _bootstrap._gcd_import ( name [ level : ] , package , level ) file & quot ; & lt ; frozen importlib._bootstrap & gt ; & quot ; , line 1014 , _gcd_import file & quot ; & lt ; frozen importlib._bootstrap & gt ; & quot ; , line 991 , _find_and_load file & quot ; & lt ; frozen importlib._bootstrap & gt ; & quot ; , line 961 , _find_and_load_unlocked file & quot ; & lt ; frozen importlib._bootstrap & gt ; & quot ; , line 219 , _call_with_frames_removed file & quot ; & lt ; frozen importlib._bootstrap & gt ; & quot ; , line 1014 , _gcd_import file & quot ; & lt ; frozen importlib._bootstrap & gt ; & quot ; , line 991 , _find_and_load file & quot ; & lt ; frozen importlib._bootstrap & gt ; & quot ; , line 975 , _find_and_load_unlocked file & quot ; & lt ; frozen importlib._bootstrap & gt ; & quot ; , line 671 , _load_unlocked file & quot ; & lt ; frozen importlib._bootstrap_external & gt ; & quot ; , line 783 , exec_module file & quot ; & lt ; frozen importlib._bootstrap & gt ; & quot ; , line 219 , _call_with_frames_removed file & quot ; c : \users\lenovo\appdata\local\packages\pythonsoftwarefoundation.python.3.8_qbz5n2kfra8p0\localcache\local-packages\python38\site-packages\chatter\__init__.py & quot ; , line 1 , & lt ; module & gt ; base import chatter , chatterauth modulenotfounderror : module named & # 39 ; base & # 39 ;
source code ?
& # 39 ; one good tutorial watch & # 39 ; & # 39 ; asking
write hundred query want hand ? ?
sir , giving response predefined sentence , ml .and learns word wrote ( miss single letter prewritten sentence give none.is self learning chatbot chatbot ? ?
done everything exact , getting & # 39 ; nltk_data & # 39 ; error . using conda env mac . check site_packages folder
hello , facing problem getting output . even tried replaced folder bot folder ( context ) error message : c : \users\admin\desktop\bot & gt ; python sample.py traceback ( recent call last ) : file & quot ; sample.py & quot ; , line 2 , & lt ; module & gt ; chatterbot import chatbot file & quot ; c : \users\admin\appdata\local\programs\python\python38\lib\site-packages\chatterbot\__init__.py & quot ; , line 4 , & lt ; module & gt ; .chatterbot import chatbot file & quot ; c : \users\admin\appdata\local\programs\python\python38\lib\site-packages\chatterbot\chatterbot.py & quot ; , line 3 , & lt ; module & gt ; chatterbot.logic import logicadapter file & quot ; c : \users\admin\appdata\local\programs\python\python38\lib\site-packages\chatterbot\logic\__init__.py & quot ; , line 1 , & lt ; module & gt ; chatterbot.logic.logic_adapter import logicadapter file & quot ; c : \users\admin\appdata\local\programs\python\python38\lib\site-packages\chatterbot\logic\logic_adapter.py & quot ; , line 3 , & lt ; module & gt ; chatterbot.search import indexedtextsearch file & quot ; c : \users\admin\appdata\local\programs\python\python38\lib\site-packages\chatterbot\search.py & quot ; , line 1 , & lt ; module & gt ; chatterbot.conversation import statement file & quot ; c : \users\admin\appdata\local\programs\python\python38\lib\site-packages\chatterbot\conversation.py & quot ; , line 1 , & lt ; module & gt ; pytz import utc modulenotfounderror : module named & # 39 ; pytz & # 39 ; could please help obtain solution
sir version install.it working 3.8.3
train data get better result
sir , & # 39 ; getting error even rechecking code module . please help metraceback ( recent call last ) : file & quot ; sample.py & quot ; , line 6 , & lt ; module & gt ; english_bot = chatbot ( & quot ; chatterbot & quot ; , storage_adapter= & quot ; chatterbot.storage.sqlstorageadapter & quot ; ) file & quot ; c : \python38\lib\site-packages\chatterbot\chatterbot.py & quot ; , line 35 , _init_ self.storage = utils.initialize_class ( storage_adapter , * * kwargs ) file & quot ; c : \python38\lib\site-packages\chatterbot\utils.py & quot ; , line 54 , initialize_class return class ( * args , * * kwargs ) file & quot ; c : \python38\lib\site-packages\chatterbot\storage\sql_storage.py & quot ; , line 22 , _init_ sqlalchemy import create_engine file & quot ; c : \python38\lib\site-packages\sqlalchemy\__init__.py & quot ; , line 8 , & lt ; module & gt ; . import util _util # noqa file & quot ; c : \python38\lib\site-packages\sqlalchemy\util\__init__.py & quot ; , line 14 , & lt ; module & gt ; ._collections import coerce_generator_arg # noqa file & quot ; c : \python38\lib\site-packages\sqlalchemy\util\_collections.py & quot ; , line 16 , & lt ; module & gt ; .compat import binary_types file & quot ; c : \python38\lib\site-packages\sqlalchemy\util\compat.py & quot ; , line 264 , & lt ; module & gt ; time_func = time.clock attributeerror : module & # 39 ; time & # 39 ; attribute & # 39 ; clock & # 39 ;
hi , already chatbot script based deep learning . integrate script flask framework ?
get point wise answer bot like list programming language ; answer = 1. python 2. java3 . c # etc
good
thanks video first time created chatbot alot search chatbots
plzz provide code description .
